INFO: Starting training:
        Epochs:          40
        Batch size:      32
        Learning rate:   1e-05
        Training size:   465
        Validation size: 5
        Checkpoints:     True
        Device:          cuda
        Images scaling:  0.5
        Mixed Precision: False

Epoch 1/40:   7%|███████▉                                                                                                            | 32/465 [00:22<05:08,  1.40img/s, loss (batch)=1.64]
ERROR: Detected OutOfMemoryError! Enabling checkpointing to reduce memory usage, but this slows down training. Consider enabling AMP (--amp) for fast and memory efficient training
Traceback (most recent call last):
  File "C:\Users\Nishaoqing\Desktop\Pytorch-UNet\Pytorch-UNet\train.py", line 263, in <module>
    train_model(
  File "C:\Users\Nishaoqing\Desktop\Pytorch-UNet\Pytorch-UNet\train.py", line 156, in train_model
    grad_scaler.scale(loss).backward()
  File "C:\Users\Nishaoqing\AppData\Local\Programs\Python\Python311\Lib\site-packages\torch\_tensor.py", line 581, in backward
    torch.autograd.backward(
  File "C:\Users\Nishaoqing\AppData\Local\Programs\Python\Python311\Lib\site-packages\torch\autograd\__init__.py", line 347, in backward
    _engine_run_backward(
  File "C:\Users\Nishaoqing\AppData\Local\Programs\Python\Python311\Lib\site-packages\torch\autograd\graph.py", line 825, in _engine_run_backward
    return Variable._execution_engine.run_backward(  # Calls into the C++ engine to run the backward pass
           ^^^^^^^^^^^^^^^^^^^^^^^^^^^^^^^^^^^^^^^^^^^^^^^^^^^^^^^^^^^^^^^^^^^^^^^^^^^^^^^^^^^^^^^^^^^^^^
torch.OutOfMemoryError: CUDA out of memory. Tried to allocate 1.22 GiB. GPU 0 has a total capacity of 23.99 GiB of which 0 bytes is free. Of the allocated memory 26.62 GiB is allocated by PyTorch, and 2.37 GiB is reserved by PyTorch but unallocated. If reserved but unallocated memory is large try setting PYTORCH_CUDA_ALLOC_CONF=expandable_segments:True to avoid fragmentation.  See documentation for Memory Management  (https://pytorch.org/docs/stable/notes/cuda.html#environment-variables)
During handling of the above exception, another exception occurred:
Traceback (most recent call last):
  File "C:\Users\Nishaoqing\Desktop\Pytorch-UNet\Pytorch-UNet\train.py", line 278, in <module>
    model.use_checkpointing()
  File "C:\Users\Nishaoqing\Desktop\Pytorch-UNet\Pytorch-UNet\unet\unet_model.py", line 39, in use_checkpointing
    self.inc = torch.utils.checkpoint(self.inc)
               ^^^^^^^^^^^^^^^^^^^^^^^^^^^^^^^^
TypeError: 'module' object is not callable